Traceback (most recent call last):
  File "/opt/hostedtoolcache/Python/3.9.12/x64/lib/python3.9/site-packages/jupyter_cache/executors/utils.py", line 51, in single_nb_execution
    executenb(
  File "/opt/hostedtoolcache/Python/3.9.12/x64/lib/python3.9/site-packages/nbclient/client.py", line 1204, in execute
    return NotebookClient(nb=nb, resources=resources, km=km, **kwargs).execute()
  File "/opt/hostedtoolcache/Python/3.9.12/x64/lib/python3.9/site-packages/nbclient/util.py", line 84, in wrapped
    return just_run(coro(*args, **kwargs))
  File "/opt/hostedtoolcache/Python/3.9.12/x64/lib/python3.9/site-packages/nbclient/util.py", line 62, in just_run
    return loop.run_until_complete(coro)
  File "/opt/hostedtoolcache/Python/3.9.12/x64/lib/python3.9/asyncio/base_events.py", line 647, in run_until_complete
    return future.result()
  File "/opt/hostedtoolcache/Python/3.9.12/x64/lib/python3.9/site-packages/nbclient/client.py", line 663, in async_execute
    await self.async_execute_cell(
  File "/opt/hostedtoolcache/Python/3.9.12/x64/lib/python3.9/site-packages/nbclient/client.py", line 965, in async_execute_cell
    await self._check_raise_for_error(cell, cell_index, exec_reply)
  File "/opt/hostedtoolcache/Python/3.9.12/x64/lib/python3.9/site-packages/nbclient/client.py", line 862, in _check_raise_for_error
    raise CellExecutionError.from_cell_and_msg(cell, exec_reply_content)
nbclient.exceptions.CellExecutionError: An error occurred while executing the following cell:
------------------
ev.tbl <- read.delim(ev.fname, na.strings="n/a", stringsAsFactors=FALSE);
      if (length(which(is.na(ev.tbl$onset))) > 0) { stop("is.na(ev.tbl$onset)"); }
      ev.vec <- round(ev.tbl$onset/TR);   # integer onsets in TRs

fname <- paste0(in.path, "sub-", sub.ids[2], "_ses-wave1bas_task-Stroop_acq-mb4AP_run-1_events.tsv")
if (file.exists(fname)) {
  ev.tbl <- read.delim(fname, na.strings="n/a", stringsAsFactors=FALSE);
  
  print(head(ev.tbl));  # show first rows of the table

  ev.vec <- round(ev.tbl$onset/TR);   # integer onsets in TRs
  plot(x=ev.vec, y=rep(0, length(ev.vec)), pch="|", xlab="event onset, in TR", ylab="");
}

------------------

Error in read.table(file = file, header = header, sep = sep, quote = quote, : object 'ev.fname' not found
Traceback:

1. read.delim(ev.fname, na.strings = "n/a", stringsAsFactors = FALSE)
2. read.table(file = file, header = header, sep = sep, quote = quote, 
 .     dec = dec, fill = fill, comment.char = comment.char, ...)
ERROR: Error in read.table(file = file, header = header, sep = sep, quote = quote, : object 'ev.fname' not found


